Workbook

Sheet Dashboard
B1: PAINEL DO CLIENTE | S1: Produto | T1: Crédito (R$)
N2: {=tblClientes[Cliente]} -> João Silva | S2: {=IFERROR(INDEX(_xlfn.SORTBY(_xlfn._xlws.FILTER(tblConsorcios[Produto],tblConsorcios[Parcela Mensal (R$)]<=$D$7),_xlfn._xlws.FILTER(tblConsorcios[Valor da Carta (R$)],tblConsorcios[Parcela Mensal (R$)]<=$D$7),-1),_xlfn.SEQUENCE(5)),"")} -> Imóvel IE600 – 240m | T2: {=IFERROR(INDEX(_xlfn.SORTBY(_xlfn._xlws.FILTER(tblConsorcios[Valor da Carta (R$)],tblConsorcios[Parcela Mensal (R$)]<=$D$7),_xlfn._xlws.FILTER(tblConsorcios[Valor da Carta (R$)],tblConsorcios[Parcela Mensal (R$)]<=$D$7),-1),_xlfn.SEQUENCE(5)),"")} -> 600000
N3: Maria Souza | S3: Imóvel IE600 – 220m | T3: 600000
B4: Selecione o cliente: | C4: JANDIRINHA | G4: RESUMO RÁPIDO DO CLIENTE | N4: Carlos Pereira | S4: Imóvel IE600 – 200m | T4: 600000
N5: JANDIRINHA | S5: Imóvel IE580 – 240m | T5: 580000
B6: =$C$4 -> JANDIRINHA | G6: Maior carta pagável | J6: Produtos que cabem | N6: 0 | S6: Imóvel IE580 – 220m | T6: 580000
B7: Dividendo mensal | D7: =_xlfn.XLOOKUP($C$4,tblClientes[Cliente],tblClientes[Dividendo Mensal (R$)]) -> 4550 | G7: =IFERROR($D$8,0) -> 600000 | J7: =IFERROR($D$9,0) -> 63 | N7: 0
B8: Maior carta pagável | D8: =_xlfn.XLOOKUP($C$4,tblClientes[Cliente],tblClientes[Maior Carta Pagável (R$)]) -> 600000 | N8: 0
B9: Produtos que cabem | D9: =_xlfn.XLOOKUP($C$4,tblClientes[Cliente],tblClientes[Produtos Elegíveis]) -> 63 | G9: Menor parcela (entrada) | J9: Maior parcela que cabe | N9: 0
B10: Bem/Produto | C10: Crédito | D10: Parcela | E10: Folga/mês | G10: {=IFERROR(MIN(_xlfn._xlws.FILTER(tblConsorcios[Parcela Mensal (R$)],tblConsorcios[Parcela Mensal (R$)]<=$D$7)),0)} -> 644 | J10: {=IFERROR(MAX(_xlfn._xlws.FILTER(tblConsorcios[Parcela Mensal (R$)],tblConsorcios[Parcela Mensal (R$)]<=$D$7)),0)} -> 3804 | N10: 0
B11: {=IFERROR(_xlfn.SORTBY(_xlfn._xlws.FILTER(tblConsorcios[Produto],tblConsorcios[Parcela Mensal (R$)]<=$D$7),_xlfn._xlws.FILTER(tblConsorcios[Parcela Mensal (R$)],tblConsorcios[Parcela Mensal (R$)]<=$D$7),-1),"—")} -> Imóvel IE600 – 200m | C11: {=IFERROR(_xlfn.SORTBY(_xlfn._xlws.FILTER(tblConsorcios[Valor da Carta (R$)],tblConsorcios[Parcela Mensal (R$)]<=$D$7),_xlfn._xlws.FILTER(tblConsorcios[Parcela Mensal (R$)],tblConsorcios[Parcela Mensal (R$)]<=$D$7),-1),"")} -> 600000 | D11: {=IFERROR(_xlfn.SORTBY(_xlfn._xlws.FILTER(tblConsorcios[Parcela Mensal (R$)],tblConsorcios[Parcela Mensal (R$)]<=$D$7),_xlfn._xlws.FILTER(tblConsorcios[Parcela Mensal (R$)],tblConsorcios[Parcela Mensal (R$)]<=$D$7),-1),"")} -> 3804 | E11: {=IFERROR($D$7-_xlfn.SORTBY(_xlfn._xlws.FILTER(tblConsorcios[Parcela Mensal (R$)],tblConsorcios[Parcela Mensal (R$)]<=$D$7),_xlfn._xlws.FILTER(tblConsorcios[Parcela Mensal (R$)],tblConsorcios[Parcela Mensal (R$)]<=$D$7),-1),"")} -> 746 | N11: 0
B12: Imóvel IE580 – 200m | C12: 580000 | D12: 3677.2 | E12: 872.8 | G12: Comprometimento máx. (parcela/dividendo) | J12: Carta recomendada (maior que cabe) | N12: 0
B13: Imóvel IE550 – 200m | C13: 550000 | D13: 3487 | E13: 1063 | G13: {=IFERROR(MAX(_xlfn._xlws.FILTER(tblConsorcios[Parcela Mensal (R$)],tblConsorcios[Parcela Mensal (R$)]<=$D$7))/$D$7,0)} -> 0.83604396 | J13: {=IFERROR(INDEX(_xlfn._xlws.FILTER(tblConsorcios[Produto],(tblConsorcios[Parcela Mensal (R$)]<=$D$7)*(tblConsorcios[Valor da Carta (R$)]=$D$8)),1),"—")} -> Imóvel IE600 – 240m | N13: 0
B14: Imóvel IE600 – 220m | C14: 600000 | D14: 3485.45 | E14: 1064.55 | N14: 0
B15: Imóvel IE580 – 220m | C15: 580000 | D15: 3369.27 | E15: 1180.73 | N15: 0
B16: Imóvel IE530 – 200m | C16: 530000 | D16: 3360.2 | E16: 1189.8
B17: Imóvel IE600 – 240m | C17: 600000 | D17: 3220 | E17: 1330
B18: Imóvel IE550 – 220m | C18: 550000 | D18: 3195 | E18: 1355
B19: Imóvel IE500 – 200m | C19: 500000 | D19: 3170 | E19: 1380
B20: Imóvel IE580 – 240m | C20: 580000 | D20: 3112.67 | E20: 1437.33
B21: Imóvel IE530 – 220m | C21: 530000 | D21: 3078.82 | E21: 1471.18
B22: Imóvel IE480 – 200m | C22: 480000 | D22: 3043.2 | E22: 1506.8
B23: Imóvel IE550 – 240m | C23: 550000 | D23: 2951.67 | E23: 1598.33
B24: Imóvel IE500 – 220m | C24: 500000 | D24: 2904.55 | E24: 1645.45
B25: Imóvel IE450 – 200m | C25: 450000 | D25: 2853 | E25: 1697
B26: Imóvel IE530 – 240m | C26: 530000 | D26: 2844.33 | E26: 1705.67
B27: Imóvel IE480 – 220m | C27: 480000 | D27: 2788.36 | E27: 1761.64
... B73: Imóvel IE120 – 240m | C73: 120000 | D73: 644 | E73: 3906

Sheet Cartões
B1: CARTÕES POR CLIENTE — TOP 10 OPORTUNIDADES
B2: 🟩 tem oportunidade 🟥 sem produto elegível ⬜ aguardando dados | Top 10 maiores parcelas que cabem | Capacidade: 120 clientes
B4: =IF(Clientes!A2="","— aguardando dados —",Clientes!A2) -> João Silva | G4: =IF(Clientes!A3="","— aguardando dados —",Clientes!A3) -> Maria Souza
B5: Dividendo mensal | D5: =IF(Clientes!A2="","",Clientes!B2) -> 1500 | G5: Dividendo mensal | I5: =IF(Clientes!A3="","",Clientes!B3) -> 3200
B6: Maior carta pagável | D6: =IF(Clientes!A2="","",Clientes!C2) -> 240000 | G6: Maior carta pagável | I6: =IF(Clientes!A3="","",Clientes!C3) -> 580000
B7: Produtos que cabem | D7: =IF(Clientes!A2="","",Clientes!D2) -> 23 | G7: Produtos que cabem | I7: =IF(Clientes!A3="","",Clientes!D3) -> 56
B8: Bem/Produto | C8: Crédito | D8: Parcela | E8: Folga/mês | G8: Bem/Produto | H8: Crédito | I8: Parcela | J8: Folga/mês
B9: {=IFERROR(INDEX(_xlfn.SORTBY(_xlfn._xlws.FILTER(tblConsorcios[Produto],tblConsorcios[Parcela Mensal (R$)]<=Clientes!$B$2),_xlfn._xlws.FILTER(tblConsorcios[Parcela Mensal (R$)],tblConsorcios[Parcela Mensal (R$)]<=Clientes!$B$2),-1),_xlfn.SEQUENCE(10)),"")} -> Imóvel IE230 – 200m | C9: {=IFERROR(INDEX(_xlfn.SORTBY(_xlfn._xlws.FILTER(tblConsorcios[Valor da Carta (R$)],tblConsorcios[Parcela Mensal (R$)]<=Clientes!$B$2),_xlfn._xlws.FILTER(tblConsorcios[Parcela Mensal (R$)],tblConsorcios[Parcela Mensal (R$)]<=Clientes!$B$2),-1),_xlfn.SEQUENCE(10)),"")} -> 230000 | D9: {=IFERROR(INDEX(_xlfn.SORTBY(_xlfn._xlws.FILTER(tblConsorcios[Parcela Mensal (R$)],tblConsorcios[Parcela Mensal (R$)]<=Clientes!$B$2),_xlfn._xlws.FILTER(tblConsorcios[Parcela Mensal (R$)],tblConsorcios[Parcela Mensal (R$)]<=Clientes!$B$2),-1),_xlfn.SEQUENCE(10)),"")} -> 1458.2 | E9: {=IFERROR(Clientes!$B$2-INDEX(_xlfn.SORTBY(_xlfn._xlws.FILTER(tblConsorcios[Parcela Mensal (R$)],tblConsorcios[Parcela Mensal (R$)]<=Clientes!$B$2),_xlfn._xlws.FILTER(tblConsorcios[Parcela Mensal (R$)],tblConsorcios[Parcela Mensal (R$)]<=Clientes!$B$2),-1),_xlfn.SEQUENCE(10)),"")} -> 41.8 | G9: {=IFERROR(INDEX(_xlfn.SORTBY(_xlfn._xlws.FILTER(tblConsorcios[Produto],tblConsorcios[Parcela Mensal (R$)]<=Clientes!$B$3),_xlfn._xlws.FILTER(tblConsorcios[Parcela Mensal (R$)],tblConsorcios[Parcela Mensal (R$)]<=Clientes!$B$3),-1),_xlfn.SEQUENCE(10)),"")} -> Imóvel IE550 – 220m | H9: {=IFERROR(INDEX(_xlfn.SORTBY(_xlfn._xlws.FILTER(tblConsorcios[Valor da Carta (R$)],tblConsorcios[Parcela Mensal (R$)]<=Clientes!$B$3),_xlfn._xlws.FILTER(tblConsorcios[Parcela Mensal (R$)],tblConsorcios[Parcela Mensal (R$)]<=Clientes!$B$3),-1),_xlfn.SEQUENCE(10)),"")} -> 550000 | I9: {=IFERROR(INDEX(_xlfn.SORTBY(_xlfn._xlws.FILTER(tblConsorcios[Parcela Mensal (R$)],tblConsorcios[Parcela Mensal (R$)]<=Clientes!$B$3),_xlfn._xlws.FILTER(tblConsorcios[Parcela Mensal (R$)],tblConsorcios[Parcela Mensal (R$)]<=Clientes!$B$3),-1),_xlfn.SEQUENCE(10)),"")} -> 3195 | J9: {=IFERROR(Clientes!$B$3-INDEX(_xlfn.SORTBY(_xlfn._xlws.FILTER(tblConsorcios[Parcela Mensal (R$)],tblConsorcios[Parcela Mensal (R$)]<=Clientes!$B$3),_xlfn._xlws.FILTER(tblConsorcios[Parcela Mensal (R$)],tblConsorcios[Parcela Mensal (R$)]<=Clientes!$B$3),-1),_xlfn.SEQUENCE(10)),"")} -> 5
B10: Imóvel IE220 – 200m | C10: 220000 | D10: 1394.8 | E10: 105.2 | G10: Imóvel IE500 – 200m | H10: 500000 | I10: 3170 | J10: 30
B11: Imóvel IE240 – 220m | C11: 240000 | D11: 1394.18 | E11: 105.82 | G11: Imóvel IE580 – 240m | H11: 580000 | I11: 3112.67 | J11: 87.33
B12: Imóvel IE230 – 220m | C12: 230000 | D12: 1336.09 | E12: 163.91 | G12: Imóvel IE530 – 220m | H12: 530000 | I12: 3078.82 | J12: 121.18
B13: Imóvel IE240 – 240m | C13: 240000 | D13: 1288 | E13: 212 | G13: Imóvel IE480 – 200m | H13: 480000 | I13: 3043.2 | J13: 156.8
B14: Imóvel IE220 – 220m | C14: 220000 | D14: 1278 | E14: 222 | G14: Imóvel IE550 – 240m | H14: 550000 | I14: 2951.67 | J14: 248.33
B15: Imóvel IE200 – 200m | C15: 200000 | D15: 1268 | E15: 232 | G15: Imóvel IE500 – 220m | H15: 500000 | I15: 2904.55 | J15: 295.45
B16: Imóvel IE230 – 240m | C16: 230000 | D16: 1234.33 | E16: 265.67 | G16: Imóvel IE450 – 200m | H16: 450000 | I16: 2853 | J16: 347
B17: Imóvel IE220 – 240m | C17: 220000 | D17: 1180.67 | E17: 319.33 | G17: Imóvel IE530 – 240m | H17: 530000 | I17: 2844.33 | J17: 355.67
B18: Imóvel IE200 – 220m | C18: 200000 | D18: 1161.82 | E18: 338.18 | G18: Imóvel IE480 – 220m | H18: 480000 | I18: 2788.36 | J18: 411.64
B20: =IF(Clientes!A4="","— aguardando dados —",Clientes!A4) -> Carlos Pereira | G20: =IF(Clientes!A5="","— aguardando dados —",Clientes!A5) -> JANDIRINHA
B21: Dividendo mensal | D21: =IF(Clientes!A4="","",Clientes!B4) -> 800 | G21: Dividendo mensal | I21: =IF(Clientes!A5="","",Clientes!B5) -> 4550
B22: Maior carta pagável | D22: =IF(Clientes!A4="","",Clientes!C4) -> 140000 | G22: Maior carta pagável | I22: =IF(Clientes!A5="","",Clientes!C5) -> 600000
B23: Produtos que cabem | D23: =IF(Clientes!A4="","",Clientes!D4) -> 6 | G23: Produtos que cabem | I23: =IF(Clientes!A5="","",Clientes!D5) -> 63
B24: Bem/Produto | C24: Crédito | D24: Parcela | E24: Folga/mês | G24: Bem/Produto | H24: Crédito | I24: Parcela | J24: Folga/mês
B25: {=IFERROR(INDEX(_xlfn.SORTBY(_xlfn._xlws.FILTER(tblConsorcios[Produto],tblConsorcios[Parcela Mensal (R$)]<=Clientes!$B$4),_xlfn._xlws.FILTER(tblConsorcios[Parcela Mensal (R$)],tblConsorcios[Parcela Mensal (R$)]<=Clientes!$B$4),-1),_xlfn.SEQUENCE(10)),"")} -> Imóvel IE120 – 200m | C25: {=IFERROR(INDEX(_xlfn.SORTBY(_xlfn._xlws.FILTER(tblConsorcios[Valor da Carta (R$)],tblConsorcios[Parcela Mensal (R$)]<=Clientes!$B$4),_xlfn._xlws.FILTER(tblConsorcios[Parcela Mensal (R$)],tblConsorcios[Parcela Mensal (R$)]<=Clientes!$B$4),-1),_xlfn.SEQUENCE(10)),"")} -> 120000 | D25: {=IFERROR(INDEX(_xlfn.SORTBY(_xlfn._xlws.FILTER(tblConsorcios[Parcela Mensal (R$)],tblConsorcios[Parcela Mensal (R$)]<=Clientes!$B$4),_xlfn._xlws.FILTER(tblConsorcios[Parcela Mensal (R$)],tblConsorcios[Parcela Mensal (R$)]<=Clientes!$B$4),-1),_xlfn.SEQUENCE(10)),"")} -> 760.8 | E25: {=IFERROR(Clientes!$B$4-INDEX(_xlfn.SORTBY(_xlfn._xlws.FILTER(tblConsorcios[Parcela Mensal (R$)],tblConsorcios[Parcela Mensal (R$)]<=Clientes!$B$4),_xlfn._xlws.FILTER(tblConsorcios[Parcela Mensal (R$)],tblConsorcios[Parcela Mensal (R$)]<=Clientes!$B$4),-1),_xlfn.SEQUENCE(10)),"")} -> 39.2 | G25: {=IFERROR(INDEX(_xlfn.SORTBY(_xlfn._xlws.FILTER(tblConsorcios[Produto],tblConsorcios[Parcela Mensal (R$)]<=Clientes!$B$5),_xlfn._xlws.FILTER(tblConsorcios[Parcela Mensal (R$)],tblConsorcios[Parcela Mensal (R$)]<=Clientes!$B$5),-1),_xlfn.SEQUENCE(10)),"")} -> Imóvel IE600 – 200m | H25: {=IFERROR(INDEX(_xlfn.SORTBY(_xlfn._xlws.FILTER(tblConsorcios[Valor da Carta (R$)],tblConsorcios[Parcela Mensal (R$)]<=Clientes!$B$5),_xlfn._xlws.FILTER(tblConsorcios[Parcela Mensal (R$)],tblConsorcios[Parcela Mensal (R$)]<=Clientes!$B$5),-1),_xlfn.SEQUENCE(10)),"")} -> 600000 | I25: {=IFERROR(INDEX(_xlfn.SORTBY(_xlfn._xlws.FILTER(tblConsorcios[Parcela Mensal (R$)],tblConsorcios[Parcela Mensal (R$)]<=Clientes!$B$5),_xlfn._xlws.FILTER(tblConsorcios[Parcela Mensal (R$)],tblConsorcios[Parcela Mensal (R$)]<=Clientes!$B$5),-1),_xlfn.SEQUENCE(10)),"")} -> 3804 | J25: {=IFERROR(Clientes!$B$5-INDEX(_xlfn.SORTBY(_xlfn._xlws.FILTER(tblConsorcios[Parcela Mensal (R$)],tblConsorcios[Parcela Mensal (R$)]<=Clientes!$B$5),_xlfn._xlws.FILTER(tblConsorcios[Parcela Mensal (R$)],tblConsorcios[Parcela Mensal (R$)]<=Clientes!$B$5),-1),_xlfn.SEQUENCE(10)),"")} -> 746
B26: Imóvel IE130 – 220m | C26: 130000 | D26: 755.18 | E26: 44.82 | G26: Imóvel IE580 – 200m | H26: 580000 | I26: 3677.2 | J26: 872.8
B27: Imóvel IE140 – 240m | C27: 140000 | D27: 751.33 | E27: 48.67 | G27: Imóvel IE550 – 200m | H27: 550000 | I27: 3487 | J27: 1063
B28: Imóvel IE130 – 240m | C28: 130000 | D28: 697.67 | E28: 102.33 | G28: Imóvel IE600 – 220m | H28: 600000 | I28: 3485.45 | J28: 1064.55
B29: Imóvel IE120 – 220m | C29: 120000 | D29: 697.09 | E29: 102.91 | G29: Imóvel IE580 – 220m | H29: 580000 | I29: 3369.27 | J29: 1180.73
B30: Imóvel IE120 – 240m | C30: 120000 | D30: 644 | E30: 156 | G30: Imóvel IE530 – 200m | H30: 530000 | I30: 3360.2 | J30: 1189.8
G31: Imóvel IE600 – 240m | H31: 600000 | I31: 3220 | J31: 1330
G32: Imóvel IE550 – 220m | H32: 550000 | I32: 3195 | J32: 1355
G33: Imóvel IE500 – 200m | H33: 500000 | I33: 3170 | J33: 1380
G34: Imóvel IE580 – 240m | H34: 580000 | I34: 3112.67 | J34: 1437.33
B36: =IF(Clientes!A6="","— aguardando dados —",Clientes!A6) -> — aguardando dados — | G36: =IF(Clientes!A7="","— aguardando dados —",Clientes!A7) -> — aguardando dados —
B37: Dividendo mensal | D37: =IF(Clientes!A6="","",Clientes!B6) | G37: Dividendo mensal | I37: =IF(Clientes!A7="","",Clientes!B7)
B38: Maior carta pagável | D38: =IF(Clientes!A6="","",Clientes!C6) | G38: Maior carta pagável | I38: =IF(Clientes!A7="","",Clientes!C7)
B39: Produtos que cabem | D39: =IF(Clientes!A6="","",Clientes!D6) | G39: Produtos que cabem | I39: =IF(Clientes!A7="","",Clientes!D7)
B40: Bem/Produto | C40: Crédito | D40: Parcela | E40: Folga/mês | G40: Bem/Produto | H40: Crédito | I40: Parcela | J40: Folga/mês
B41: {=IFERROR(INDEX(_xlfn.SORTBY(_xlfn._xlws.FILTER(tblConsorcios[Produto],tblConsorcios[Parcela Mensal (R$)]<=Clientes!$B$6),_xlfn._xlws.FILTER(tblConsorcios[Parcela Mensal (R$)],tblConsorcios[Parcela Mensal (R$)]<=Clientes!$B$6),-1),_xlfn.SEQUENCE(10)),"")} | C41: {=IFERROR(INDEX(_xlfn.SORTBY(_xlfn._xlws.FILTER(tblConsorcios[Valor da Carta (R$)],tblConsorcios[Parcela Mensal (R$)]<=Clientes!$B$6),_xlfn._xlws.FILTER(tblConsorcios[Parcela Mensal (R$)],tblConsorcios[Parcela Mensal (R$)]<=Clientes!$B$6),-1),_xlfn.SEQUENCE(10)),"")} | D41: {=IFERROR(INDEX(_xlfn.SORTBY(_xlfn._xlws.FILTER(tblConsorcios[Parcela Mensal (R$)],tblConsorcios[Parcela Mensal (R$)]<=Clientes!$B$6),_xlfn._xlws.FILTER(tblConsorcios[Parcela Mensal (R$)],tblConsorcios[Parcela Mensal (R$)]<=Clientes!$B$6),-1),_xlfn.SEQUENCE(10)),"")} | E41: {=IFERROR(Clientes!$B$6-INDEX(_xlfn.SORTBY(_xlfn._xlws.FILTER(tblConsorcios[Parcela Mensal (R$)],tblConsorcios[Parcela Mensal (R$)]<=Clientes!$B$6),_xlfn._xlws.FILTER(tblConsorcios[Parcela Mensal (R$)],tblConsorcios[Parcela Mensal (R$)]<=Clientes!$B$6),-1),_xlfn.SEQUENCE(10)),"")} | G41: {=IFERROR(INDEX(_xlfn.SORTBY(_xlfn._xlws.FILTER(tblConsorcios[Produto],tblConsorcios[Parcela Mensal (R$)]<=Clientes!$B$7),_xlfn._xlws.FILTER(tblConsorcios[Parcela Mensal (R$)],tblConsorcios[Parcela Mensal (R$)]<=Clientes!$B$7),-1),_xlfn.SEQUENCE(10)),"")} | H41: {=IFERROR(INDEX(_xlfn.SORTBY(_xlfn._xlws.FILTER(tblConsorcios[Valor da Carta (R$)],tblConsorcios[Parcela Mensal (R$)]<=Clientes!$B$7),_xlfn._xlws.FILTER(tblConsorcios[Parcela Mensal (R$)],tblConsorcios[Parcela Mensal (R$)]<=Clientes!$B$7),-1),_xlfn.SEQUENCE(10)),"")} | I41: {=IFERROR(INDEX(_xlfn.SORTBY(_xlfn._xlws.FILTER(tblConsorcios[Parcela Mensal (R$)],tblConsorcios[Parcela Mensal (R$)]<=Clientes!$B$7),_xlfn._xlws.FILTER(tblConsorcios[Parcela Mensal (R$)],tblConsorcios[Parcela Mensal (R$)]<=Clientes!$B$7),-1),_xlfn.SEQUENCE(10)),"")} | J41: {=IFERROR(Clientes!$B$7-INDEX(_xlfn.SORTBY(_xlfn._xlws.FILTER(tblConsorcios[Parcela Mensal (R$)],tblConsorcios[Parcela Mensal (R$)]<=Clientes!$B$7),_xlfn._xlws.FILTER(tblConsorcios[Parcela Mensal (R$)],tblConsorcios[Parcela Mensal (R$)]<=Clientes!$B$7),-1),_xlfn.SEQUENCE(10)),"")}
B52: =IF(Clientes!A8="","— aguardando dados —",Clientes!A8) -> — aguardando dados — | G52: =IF(Clientes!A9="","— aguardando dados —",Clientes!A9) -> — aguardando dados —
B53: Dividendo mensal | D53: =IF(Clientes!A8="","",Clientes!B8) | G53: Dividendo mensal | I53: =IF(Clientes!A9="","",Clientes!B9)
...

Sheet Consórcios
A1: Produto | B1: Código | C1: Valor da Carta (R$) | D1: Prazo (meses) | E1: Taxa Adm Total (%) | F1: Parcela 1ª a 12ª (R$) | G1: Parcela Mensal (R$)
A2: Imóvel IE600 – 240m | B2: IE600 | C2: 600000 | D2: 240 | E2: 0.268 | F2: 3820 | G2: 3220
A3: Imóvel IE600 – 220m | B3: IE600 | C3: 600000 | D3: 220 | E3: 0.258 | F3: 4085.45 | G3: 3485.45
A4: Imóvel IE600 – 200m | B4: IE600 | C4: 600000 | D4: 200 | E4: 0.248 | F4: 4404 | G4: 3804
A5: Imóvel IE580 – 240m | B5: IE580 | C5: 580000 | D5: 240 | E5: 0.268 | F5: 3692.67 | G5: 3112.67
A6: Imóvel IE580 – 220m | B6: IE580 | C6: 580000 | D6: 220 | E6: 0.258 | F6: 3949.27 | G6: 3369.27
A7: Imóvel IE580 – 200m | B7: IE580 | C7: 580000 | D7: 200 | E7: 0.248 | F7: 4257.2 | G7: 3677.2
A8: Imóvel IE550 – 240m | B8: IE550 | C8: 550000 | D8: 240 | E8: 0.268 | F8: 3501.67 | G8: 2951.67
A9: Imóvel IE550 – 220m | B9: IE550 | C9: 550000 | D9: 220 | E9: 0.258 | F9: 3745 | G9: 3195
A10: Imóvel IE550 – 200m | B10: IE550 | C10: 550000 | D10: 200 | E10: 0.248 | F10: 4037 | G10: 3487
A11: Imóvel IE530 – 240m | B11: IE530 | C11: 530000 | D11: 240 | E11: 0.268 | F11: 3374.33 | G11: 2844.33
A12: Imóvel IE530 – 220m | B12: IE530 | C12: 530000 | D12: 220 | E12: 0.258 | F12: 3608.82 | G12: 3078.82
A13: Imóvel IE530 – 200m | B13: IE530 | C13: 530000 | D13: 200 | E13: 0.248 | F13: 3890.2 | G13: 3360.2
... A64: Imóvel IE120 – 200m | B64: IE120 | C64: 120000 | D64: 200 | E64: 0.248 | F64: 880.8 | G64: 760.8

Sheet Clientes
A1: Cliente | B1: Dividendo Mensal (R$) | C1: Maior Carta Pagável (R$) | D1: Produtos Elegíveis
A2: João Silva | B2: 1500 | C2: =_xlfn.MAXIFS(tblConsorcios[Valor da Carta (R$)],tblConsorcios[Parcela Mensal (R$)],"<="&tblClientes[[#This Row],[Dividendo Mensal (R$)]]) -> 240000 | D2: =COUNTIFS(tblConsorcios[Parcela Mensal (R$)],"<="&tblClientes[[#This Row],[Dividendo Mensal (R$)]]) -> 23
A3: Maria Souza | B3: 3200 | C3: =_xlfn.MAXIFS(tblConsorcios[Valor da Carta (R$)],tblConsorcios[Parcela Mensal (R$)],"<="&tblClientes[[#This Row],[Dividendo Mensal (R$)]]) -> 580000 | D3: =COUNTIFS(tblConsorcios[Parcela Mensal (R$)],"<="&tblClientes[[#This Row],[Dividendo Mensal (R$)]]) -> 56
A4: Carlos Pereira | B4: 800 | C4: =_xlfn.MAXIFS(tblConsorcios[Valor da Carta (R$)],tblConsorcios[Parcela Mensal (R$)],"<="&tblClientes[[#This Row],[Dividendo Mensal (R$)]]) -> 140000 | D4: =COUNTIFS(tblConsorcios[Parcela Mensal (R$)],"<="&tblClientes[[#This Row],[Dividendo Mensal (R$)]]) -> 6
A5: JANDIRINHA | B5: 4550 | C5: =_xlfn.MAXIFS(tblConsorcios[Valor da Carta (R$)],tblConsorcios[Parcela Mensal (R$)],"<="&tblClientes[[#This Row],[Dividendo Mensal (R$)]]) -> 600000 | D5: =COUNTIFS(tblConsorcios[Parcela Mensal (R$)],"<="&tblClientes[[#This Row],[Dividendo Mensal (R$)]]) -> 63
C6: =_xlfn.MAXIFS(tblConsorcios[Valor da Carta (R$)],tblConsorcios[Parcela Mensal (R$)],"<="&tblClientes[[#This Row],[Dividendo Mensal (R$)]]) -> 0 | D6: =COUNTIFS(tblConsorcios[Parcela Mensal (R$)],"<="&tblClientes[[#This Row],[Dividendo Mensal (R$)]]) -> 0
C7: =_xlfn.MAXIFS(tblConsorcios[Valor da Carta (R$)],tblConsorcios[Parcela Mensal (R$)],"<="&tblClientes[[#This Row],[Dividendo Mensal (R$)]]) -> 0 | D7: =COUNTIFS(tblConsorcios[Parcela Mensal (R$)],"<="&tblClientes[[#This Row],[Dividendo Mensal (R$)]]) -> 0
C8: =_xlfn.MAXIFS(tblConsorcios[Valor da Carta (R$)],tblConsorcios[Parcela Mensal (R$)],"<="&tblClientes[[#This Row],[Dividendo Mensal (R$)]]) -> 0 | D8: =COUNTIFS(tblConsorcios[Parcela Mensal (R$)],"<="&tblClientes[[#This Row],[Dividendo Mensal (R$)]]) -> 0
C9: =_xlfn.MAXIFS(tblConsorcios[Valor da Carta (R$)],tblConsorcios[Parcela Mensal (R$)],"<="&tblClientes[[#This Row],[Dividendo Mensal (R$)]]) -> 0 | D9: =COUNTIFS(tblConsorcios[Parcela Mensal (R$)],"<="&tblClientes[[#This Row],[Dividendo Mensal (R$)]]) -> 0
C10: =_xlfn.MAXIFS(tblConsorcios[Valor da Carta (R$)],tblConsorcios[Parcela Mensal (R$)],"<="&tblClientes[[#This Row],[Dividendo Mensal (R$)]]) -> 0 | D10: =COUNTIFS(tblConsorcios[Parcela Mensal (R$)],"<="&tblClientes[[#This Row],[Dividendo Mensal (R$)]]) -> 0
C11: =_xlfn.MAXIFS(tblConsorcios[Valor da Carta (R$)],tblConsorcios[Parcela Mensal (R$)],"<="&tblClientes[[#This Row],[Dividendo Mensal (R$)]]) -> 0 | D11: =COUNTIFS(tblConsorcios[Parcela Mensal (R$)],"<="&tblClientes[[#This Row],[Dividendo Mensal (R$)]]) -> 0
C12: =_xlfn.MAXIFS(tblConsorcios[Valor da Carta (R$)],tblConsorcios[Parcela Mensal (R$)],"<="&tblClientes[[#This Row],[Dividendo Mensal (R$)]]) -> 0 | D12: =COUNTIFS(tblConsorcios[Parcela Mensal (R$)],"<="&tblClientes[[#This Row],[Dividendo Mensal (R$)]]) -> 0
C13: =_xlfn.MAXIFS(tblConsorcios[Valor da Carta (R$)],tblConsorcios[Parcela Mensal (R$)],"<="&tblClientes[[#This Row],[Dividendo Mensal (R$)]]) -> 0 | D13: =COUNTIFS(tblConsorcios[Parcela Mensal (R$)],"<="&tblClientes[[#This Row],[Dividendo Mensal (R$)]]) -> 0
C14: =_xlfn.MAXIFS(tblConsorcios[Valor da Carta (R$)],tblConsorcios[Parcela Mensal (R$)],"<="&tblClientes[[#This Row],[Dividendo Mensal (R$)]]) -> 0 | D14: =COUNTIFS(tblConsorcios[Parcela Mensal (R$)],"<="&tblClientes[[#This Row],[Dividendo Mensal (R$)]]) -> 0
C15: =_xlfn.MAXIFS(tblConsorcios[Valor da Carta (R$)],tblConsorcios[Parcela Mensal (R$)],"<="&tblClientes[[#This Row],[Dividendo Mensal (R$)]]) -> 0 | D15: =COUNTIFS(tblConsorcios[Parcela Mensal (R$)],"<="&tblClientes[[#This Row],[Dividendo Mensal (R$)]]) -> 0

Sheet Oportunidades
A1: PAINEL DE OPORTUNIDADES — CONSÓRCIOS | J1: idx | K1: Cliente | L1: Produto | M1: Valor da Carta (R$) | N1: Prazo (meses) | O1: Parcela Mensal (R$) | P1: Dividendo Mensal (R$) | Q1: Folga Mensal (R$) | R1: Elegível
A2: Regra: parcela (carta × (1 + taxa adm) ÷ prazo) ≤ dividendo mensal do cliente · Ordenado por maior folga mensal | J2: =ROW()-2 -> 0 | K2: {=IFERROR(INDEX(tblClientes[Cliente],INT($J2/ROWS(tblConsorcios[Produto]))+1),"")} -> João Silva | L2: {=IFERROR(INDEX(tblConsorcios[Produto],MOD($J2,ROWS(tblConsorcios[Produto]))+1),"")} -> Imóvel IE600 – 240m | M2: {=IFERROR(INDEX(tblConsorcios[Valor da Carta (R$)],MOD($J2,ROWS(tblConsorcios[Produto]))+1),"")} -> 600000 | N2: {=IFERROR(INDEX(tblConsorcios[Prazo (meses)],MOD($J2,ROWS(tblConsorcios[Produto]))+1),"")} -> 240 | O2: {=IFERROR(INDEX(tblConsorcios[Parcela Mensal (R$)],MOD($J2,ROWS(tblConsorcios[Produto]))+1),"")} -> 3220 | P2: {=IFERROR(INDEX(tblClientes[Dividendo Mensal (R$)],INT($J2/ROWS(tblConsorcios[Produto]))+1),"")} -> 1500 | Q2: =IF(AND(ISNUMBER(O2),ISNUMBER(P2)),P2-O2,"") -> -1720 | R2: =IF(AND(ISNUMBER(O2),ISNUMBER(P2),O2<=P2),1,0) -> 0
J3: =ROW()-2 -> 1 | K3: {=IFERROR(INDEX(tblClientes[Cliente],INT($J3/ROWS(tblConsorcios[Produto]))+1),"")} -> João Silva | L3: {=IFERROR(INDEX(tblConsorcios[Produto],MOD($J3,ROWS(tblConsorcios[Produto]))+1),"")} -> Imóvel IE600 – 220m | M3: {=IFERROR(INDEX(tblConsorcios[Valor da Carta (R$)],MOD($J3,ROWS(tblConsorcios[Produto]))+1),"")} -> 600000 | N3: {=IFERROR(INDEX(tblConsorcios[Prazo (meses)],MOD($J3,ROWS(tblConsorcios[Produto]))+1),"")} -> 220 | O3: {=IFERROR(INDEX(tblConsorcios[Parcela Mensal (R$)],MOD($J3,ROWS(tblConsorcios[Produto]))+1),"")} -> 3485.45 | P3: {=IFERROR(INDEX(tblClientes[Dividendo Mensal (R$)],INT($J3/ROWS(tblConsorcios[Produto]))+1),"")} -> 1500 | Q3: =IF(AND(ISNUMBER(O3),ISNUMBER(P3)),P3-O3,"") -> -1985.45 | R3: =IF(AND(ISNUMBER(O3),ISNUMBER(P3),O3<=P3),1,0) -> 0
A4: Total de oportunidades | C4: =SUM(R2:R9451) -> 148 | J4: =ROW()-2 -> 2 | K4: {=IFERROR(INDEX(tblClientes[Cliente],INT($J4/ROWS(tblConsorcios[Produto]))+1),"")} -> João Silva | L4: {=IFERROR(INDEX(tblConsorcios[Produto],MOD($J4,ROWS(tblConsorcios[Produto]))+1),"")} -> Imóvel IE600 – 200m | M4: {=IFERROR(INDEX(tblConsorcios[Valor da Carta (R$)],MOD($J4,ROWS(tblConsorcios[Produto]))+1),"")} -> 600000 | N4: {=IFERROR(INDEX(tblConsorcios[Prazo (meses)],MOD($J4,ROWS(tblConsorcios[Produto]))+1),"")} -> 200 | O4: {=IFERROR(INDEX(tblConsorcios[Parcela Mensal (R$)],MOD($J4,ROWS(tblConsorcios[Produto]))+1),"")} -> 3804 | P4: {=IFERROR(INDEX(tblClientes[Dividendo Mensal (R$)],INT($J4/ROWS(tblConsorcios[Produto]))+1),"")} -> 1500 | Q4: =IF(AND(ISNUMBER(O4),ISNUMBER(P4)),P4-O4,"") -> -2304 | R4: =IF(AND(ISNUMBER(O4),ISNUMBER(P4),O4<=P4),1,0) -> 0
A5: Clientes com ≥ 1 oportunidade | C5: =COUNTIF(tblClientes[Produtos Elegíveis],">0") -> 4 | J5: =ROW()-2 -> 3 | K5: {=IFERROR(INDEX(tblClientes[Cliente],INT($J5/ROWS(tblConsorcios[Produto]))+1),"")} -> João Silva | L5: {=IFERROR(INDEX(tblConsorcios[Produto],MOD($J5,ROWS(tblConsorcios[Produto]))+1),"")} -> Imóvel IE580 – 240m | M5: {=IFERROR(INDEX(tblConsorcios[Valor da Carta (R$)],MOD($J5,ROWS(tblConsorcios[Produto]))+1),"")} -> 580000 | N5: {=IFERROR(INDEX(tblConsorcios[Prazo (meses)],MOD($J5,ROWS(tblConsorcios[Produto]))+1),"")} -> 240 | O5: {=IFERROR(INDEX(tblConsorcios[Parcela Mensal (R$)],MOD($J5,ROWS(tblConsorcios[Produto]))+1),"")} -> 3112.67 | P5: {=IFERROR(INDEX(tblClientes[Dividendo Mensal (R$)],INT($J5/ROWS(tblConsorcios[Produto]))+1),"")} -> 1500 | Q5: =IF(AND(ISNUMBER(O5),ISNUMBER(P5)),P5-O5,"") -> -1612.67 | R5: =IF(AND(ISNUMBER(O5),ISNUMBER(P5),O5<=P5),1,0) -> 0
A6: Volume potencial em cartas (R$) | C6: =SUMIFS(M2:M9451,R2:R9451,1) -> 44630000 | J6: =ROW()-2 -> 4 | K6: {=IFERROR(INDEX(tblClientes[Cliente],INT($J6/ROWS(tblConsorcios[Produto]))+1),"")} -> João Silva | L6: {=IFERROR(INDEX(tblConsorcios[Produto],MOD($J6,ROWS(tblConsorcios[Produto]))+1),"")} -> Imóvel IE580 – 220m | M6: {=IFERROR(INDEX(tblConsorcios[Valor da Carta (R$)],MOD($J6,ROWS(tblConsorcios[Produto]))+1),"")} -> 580000 | N6: {=IFERROR(INDEX(tblConsorcios[Prazo (meses)],MOD($J6,ROWS(tblConsorcios[Produto]))+1),"")} -> 220 | O6: {=IFERROR(INDEX(tblConsorcios[Parcela Mensal (R$)],MOD($J6,ROWS(tblConsorcios[Produto]))+1),"")} -> 3369.27 | P6: {=IFERROR(INDEX(tblClientes[Dividendo Mensal (R$)],INT($J6/ROWS(tblConsorcios[Produto]))+1),"")} -> 1500 | Q6: =IF(AND(ISNUMBER(O6),ISNUMBER(P6)),P6-O6,"") -> -1869.27 | R6: =IF(AND(ISNUMBER(O6),ISNUMBER(P6),O6<=P6),1,0) -> 0
J7: =ROW()-2 -> 5 | K7: {=IFERROR(INDEX(tblClientes[Cliente],INT($J7/ROWS(tblConsorcios[Produto]))+1),"")} -> João Silva | L7: {=IFERROR(INDEX(tblConsorcios[Produto],MOD($J7,ROWS(tblConsorcios[Produto]))+1),"")} -> Imóvel IE580 – 200m | M7: {=IFERROR(INDEX(tblConsorcios[Valor da Carta (R$)],MOD($J7,ROWS(tblConsorcios[Produto]))+1),"")} -> 580000 | N7: {=IFERROR(INDEX(tblConsorcios[Prazo (meses)],MOD($J7,ROWS(tblConsorcios[Produto]))+1),"")} -> 200 | O7: {=IFERROR(INDEX(tblConsorcios[Parcela Mensal (R$)],MOD($J7,ROWS(tblConsorcios[Produto]))+1),"")} -> 3677.2 | P7: {=IFERROR(INDEX(tblClientes[Dividendo Mensal (R$)],INT($J7/ROWS(tblConsorcios[Produto]))+1),"")} -> 1500 | Q7: =IF(AND(ISNUMBER(O7),ISNUMBER(P7)),P7-O7,"") -> -2177.2 | R7: =IF(AND(ISNUMBER(O7),ISNUMBER(P7),O7<=P7),1,0) -> 0
A8: # | B8: Cliente | C8: Produto | D8: Valor da Carta (R$) | E8: Prazo (meses) | F8: Parcela Mensal (R$) | G8: Dividendo Mensal (R$) | H8: Folga Mensal (R$) | J8: =ROW()-2 -> 6 | K8: {=IFERROR(INDEX(tblClientes[Cliente],INT($J8/ROWS(tblConsorcios[Produto]))+1),"")} -> João Silva | L8: {=IFERROR(INDEX(tblConsorcios[Produto],MOD($J8,ROWS(tblConsorcios[Produto]))+1),"")} -> Imóvel IE550 – 240m | M8: {=IFERROR(INDEX(tblConsorcios[Valor da Carta (R$)],MOD($J8,ROWS(tblConsorcios[Produto]))+1),"")} -> 550000 | N8: {=IFERROR(INDEX(tblConsorcios[Prazo (meses)],MOD($J8,ROWS(tblConsorcios[Produto]))+1),"")} -> 240 | O8: {=IFERROR(INDEX(tblConsorcios[Parcela Mensal (R$)],MOD($J8,ROWS(tblConsorcios[Produto]))+1),"")} -> 2951.67 | P8: {=IFERROR(INDEX(tblClientes[Dividendo Mensal (R$)],INT($J8/ROWS(tblConsorcios[Produto]))+1),"")} -> 1500 | Q8: =IF(AND(ISNUMBER(O8),ISNUMBER(P8)),P8-O8,"") -> -1451.67 | R8: =IF(AND(ISNUMBER(O8),ISNUMBER(P8),O8<=P8),1,0) -> 0
A9: {=_xlfn.SEQUENCE(ROWS(_xlfn.ANCHORARRAY(B9)))} -> 1 | B9: {=_xlfn._xlws.SORT(_xlfn._xlws.FILTER(K2:Q9451,R2:R9451=1),7,-1)} -> JANDIRINHA | C9: Imóvel IE120 – 240m | D9: 120000 | E9: 240 | F9: 644 | G9: 4550 | H9: 3906 | J9: =ROW()-2 -> 7 | K9: {=IFERROR(INDEX(tblClientes[Cliente],INT($J9/ROWS(tblConsorcios[Produto]))+1),"")} -> João Silva | L9: {=IFERROR(INDEX(tblConsorcios[Produto],MOD($J9,ROWS(tblConsorcios[Produto]))+1),"")} -> Imóvel IE550 – 220m | M9: {=IFERROR(INDEX(tblConsorcios[Valor da Carta (R$)],MOD($J9,ROWS(tblConsorcios[Produto]))+1),"")} -> 550000 | N9: {=IFERROR(INDEX(tblConsorcios[Prazo (meses)],MOD($J9,ROWS(tblConsorcios[Produto]))+1),"")} -> 220 | O9: {=IFERROR(INDEX(tblConsorcios[Parcela Mensal (R$)],MOD($J9,ROWS(tblConsorcios[Produto]))+1),"")} -> 3195 | P9: {=IFERROR(INDEX(tblClientes[Dividendo Mensal (R$)],INT($J9/ROWS(tblConsorcios[Produto]))+1),"")} -> 1500 | Q9: =IF(AND(ISNUMBER(O9),ISNUMBER(P9)),P9-O9,"") -> -1695 | R9: =IF(AND(ISNUMBER(O9),ISNUMBER(P9),O9<=P9),1,0) -> 0
A10: 2 | B10: JANDIRINHA | C10: Imóvel IE120 – 220m | D10: 120000 | E10: 220 | F10: 697.09 | G10: 4550 | H10: 3852.91 | J10: =ROW()-2 -> 8 | K10: {=IFERROR(INDEX(tblClientes[Cliente],INT($J10/ROWS(tblConsorcios[Produto]))+1),"")} -> João Silva | L10: {=IFERROR(INDEX(tblConsorcios[Produto],MOD($J10,ROWS(tblConsorcios[Produto]))+1),"")} -> Imóvel IE550 – 200m | M10: {=IFERROR(INDEX(tblConsorcios[Valor da Carta (R$)],MOD($J10,ROWS(tblConsorcios[Produto]))+1),"")} -> 550000 | N10: {=IFERROR(INDEX(tblConsorcios[Prazo (meses)],MOD($J10,ROWS(tblConsorcios[Produto]))+1),"")} -> 200 | O10: {=IFERROR(INDEX(tblConsorcios[Parcela Mensal (R$)],MOD($J10,ROWS(tblConsorcios[Produto]))+1),"")} -> 3487 | P10: {=IFERROR(INDEX(tblClientes[Dividendo Mensal (R$)],INT($J10/ROWS(tblConsorcios[Produto]))+1),"")} -> 1500 | Q10: =IF(AND(ISNUMBER(O10),ISNUMBER(P10)),P10-O10,"") -> -1987 | R10: =IF(AND(ISNUMBER(O10),ISNUMBER(P10),O10<=P10),1,0) -> 0
A11: 3 | B11: JANDIRINHA | C11: Imóvel IE130 – 240m | D11: 130000 | E11: 240 | F11: 697.67 | G11: 4550 | H11: 3852.33 | J11: =ROW()-2 -> 9 | K11: {=IFERROR(INDEX(tblClientes[Cliente],INT($J11/ROWS(tblConsorcios[Produto]))+1),"")} -> João Silva | L11: {=IFERROR(INDEX(tblConsorcios[Produto],MOD($J11,ROWS(tblConsorcios[Produto]))+1),"")} -> Imóvel IE530 – 240m | M11: {=IFERROR(INDEX(tblConsorcios[Valor da Carta (R$)],MOD($J11,ROWS(tblConsorcios[Produto]))+1),"")} -> 530000 | N11: {=IFERROR(INDEX(tblConsorcios[Prazo (meses)],MOD($J11,ROWS(tblConsorcios[Produto]))+1),"")} -> 240 | O11: {=IFERROR(INDEX(tblConsorcios[Parcela Mensal (R$)],MOD($J11,ROWS(tblConsorcios[Produto]))+1),"")} -> 2844.33 | P11: {=IFERROR(INDEX(tblClientes[Dividendo Mensal (R$)],INT($J11/ROWS(tblConsorcios[Produto]))+1),"")} -> 1500 | Q11: =IF(AND(ISNUMBER(O11),ISNUMBER(P11)),P11-O11,"") -> -1344.33 | R11: =IF(AND(ISNUMBER(O11),ISNUMBER(P11),O11<=P11),1,0) -> 0
A12: 4 | B12: JANDIRINHA | C12: Imóvel IE140 – 240m | D12: 140000 | E12: 240 | F12: 751.33 | G12: 4550 | H12: 3798.67 | J12: =ROW()-2 -> 10 | K12: {=IFERROR(INDEX(tblClientes[Cliente],INT($J12/ROWS(tblConsorcios[Produto]))+1),"")} -> João Silva | L12: {=IFERROR(INDEX(tblConsorcios[Produto],MOD($J12,ROWS(tblConsorcios[Produto]))+1),"")} -> Imóvel IE530 – 220m | M12: {=IFERROR(INDEX(tblConsorcios[Valor da Carta (R$)],MOD($J12,ROWS(tblConsorcios[Produto]))+1),"")} -> 530000 | N12: {=IFERROR(INDEX(tblConsorcios[Prazo (meses)],MOD($J12,ROWS(tblConsorcios[Produto]))+1),"")} -> 220 | O12: {=IFERROR(INDEX(tblConsorcios[Parcela Mensal (R$)],MOD($J12,ROWS(tblConsorcios[Produto]))+1),"")} -> 3078.82 | P12: {=IFERROR(INDEX(tblClientes[Dividendo Mensal (R$)],INT($J12/ROWS(tblConsorcios[Produto]))+1),"")} -> 1500 | Q12: =IF(AND(ISNUMBER(O12),ISNUMBER(P12)),P12-O12,"") -> -1578.82 | R12: =IF(AND(ISNUMBER(O12),ISNUMBER(P12),O12<=P12),1,0) -> 0
A13: 5 | B13: JANDIRINHA | C13: Imóvel IE130 – 220m | D13: 130000 | E13: 220 | F13: 755.18 | G13: 4550 | H13: 3794.82 | J13: =ROW()-2 -> 11 | K13: {=IFERROR(INDEX(tblClientes[Cliente],INT($J13/ROWS(tblConsorcios[Produto]))+1),"")} -> João Silva | L13: {=IFERROR(INDEX(tblConsorcios[Produto],MOD($J13,ROWS(tblConsorcios[Produto]))+1),"")} -> Imóvel IE530 – 200m | M13: {=IFERROR(INDEX(tblConsorcios[Valor da Carta (R$)],MOD($J13,ROWS(tblConsorcios[Produto]))+1),"")} -> 530000 | N13: {=IFERROR(INDEX(tblConsorcios[Prazo (meses)],MOD($J13,ROWS(tblConsorcios[Produto]))+1),"")} -> 200 | O13: {=IFERROR(INDEX(tblConsorcios[Parcela Mensal (R$)],MOD($J13,ROWS(tblConsorcios[Produto]))+1),"")} -> 3360.2 | P13: {=IFERROR(INDEX(tblClientes[Dividendo Mensal (R$)],INT($J13/ROWS(tblConsorcios[Produto]))+1),"")} -> 1500 | Q13: =IF(AND(ISNUMBER(O13),ISNUMBER(P13)),P13-O13,"") -> -1860.2 | R13: =IF(AND(ISNUMBER(O13),ISNUMBER(P13),O13<=P13),1,0) -> 0
A14: 6 | B14: JANDIRINHA | C14: Imóvel IE120 – 200m | D14: 120000 | E14: 200 | F14: 760.8 | G14: 4550 | H14: 3789.2 | J14: =ROW()-2 -> 12 | K14: {=IFERROR(INDEX(tblClientes[Cliente],INT($J14/ROWS(tblConsorcios[Produto]))+1),"")} -> João Silva | L14: {=IFERROR(INDEX(tblConsorcios[Produto],MOD($J14,ROWS(tblConsorcios[Produto]))+1),"")} -> Imóvel IE500 – 240m | M14: {=IFERROR(INDEX(tblConsorcios[Valor da Carta (R$)],MOD($J14,ROWS(tblConsorcios[Produto]))+1),"")} -> 500000 | N14: {=IFERROR(INDEX(tblConsorcios[Prazo (meses)],MOD($J14,ROWS(tblConsorcios[Produto]))+1),"")} -> 240 | O14: {=IFERROR(INDEX(tblConsorcios[Parcela Mensal (R$)],MOD($J14,ROWS(tblConsorcios[Produto]))+1),"")} -> 2683.33 | P14: {=IFERROR(INDEX(tblClientes[Dividendo Mensal (R$)],INT($J14/ROWS(tblConsorcios[Produto]))+1),"")} -> 1500 | Q14: =IF(AND(ISNUMBER(O14),ISNUMBER(P14)),P14-O14,"") -> -1183.33 | R14: =IF(AND(ISNUMBER(O14),ISNUMBER(P14),O14<=P14),1,0) -> 0
A15: 7 | B15: JANDIRINHA | C15: Imóvel IE150 – 240m | D15: 150000 | E15: 240 | F15: 805 | G15: 4550 | H15: 3745 | J15: =ROW()-2 -> 13 | K15: {=IFERROR(INDEX(tblClientes[Cliente],INT($J15/ROWS(tblConsorcios[Produto]))+1),"")} -> João Silva | L15: {=IFERROR(INDEX(tblConsorcios[Produto],MOD($J15,ROWS(tblConsorcios[Produto]))+1),"")} -> Imóvel IE500 – 220m | M15: {=IFERROR(INDEX(tblConsorcios[Valor da Carta (R$)],MOD($J15,ROWS(tblConsorcios[Produto]))+1),"")} -> 500000 | N15: {=IFERROR(INDEX(tblConsorcios[Prazo (meses)],MOD($J15,ROWS(tblConsorcios[Produto]))+1),"")} -> 220 | O15: {=IFERROR(INDEX(tblConsorcios[Parcela Mensal (R$)],MOD($J15,ROWS(tblConsorcios[Produto]))+1),"")} -> 2904.55 | P15: {=IFERROR(INDEX(tblClientes[Dividendo Mensal (R$)],INT($J15/ROWS(tblConsorcios[Produto]))+1),"")} -> 1500 | Q15: =IF(AND(ISNUMBER(O15),ISNUMBER(P15)),P15-O15,"") -> -1404.55 | R15: =IF(AND(ISNUMBER(O15),ISNUMBER(P15),O15<=P15),1,0) -> 0
A16: 8 | B16: JANDIRINHA | C16: Imóvel IE140 – 220m | D16: 140000 | E16: 220 | F16: 813.27 | G16: 4550 | H16: 3736.73 | J16: =ROW()-2 -> 14 | K16: {=IFERROR(INDEX(tblClientes[Cliente],INT($J16/ROWS(tblConsorcios[Produto]))+1),"")} -> João Silva | L16: {=IFERROR(INDEX(tblConsorcios[Produto],MOD($J16,ROWS(tblConsorcios[Produto]))+1),"")} -> Imóvel IE500 – 200m | M16: {=IFERROR(INDEX(tblConsorcios[Valor da Carta (R$)],MOD($J16,ROWS(tblConsorcios[Produto]))+1),"")} -> 500000 | N16: {=IFERROR(INDEX(tblConsorcios[Prazo (meses)],MOD($J16,ROWS(tblConsorcios[Produto]))+1),"")} -> 200 | O16: {=IFERROR(INDEX(tblConsorcios[Parcela Mensal (R$)],MOD($J16,ROWS(tblConsorcios[Produto]))+1),"")} -> 3170 | P16: {=IFERROR(INDEX(tblClientes[Dividendo Mensal (R$)],INT($J16/ROWS(tblConsorcios[Produto]))+1),"")} -> 1500 | Q16: =IF(AND(ISNUMBER(O16),ISNUMBER(P16)),P16-O16,"") -> -1670 | R16: =IF(AND(ISNUMBER(O16),ISNUMBER(P16),O16<=P16),1,0) -> 0
A17: 9 | B17: JANDIRINHA | C17: Imóvel IE130 – 200m | D17: 130000 | E17: 200 | F17: 824.2 | G17: 4550 | H17: 3725.8 | J17: =ROW()-2 -> 15 | K17: {=IFERROR(INDEX(tblClientes[Cliente],INT($J17/ROWS(tblConsorcios[Produto]))+1),"")} -> João Silva | L17: {=IFERROR(INDEX(tblConsorcios[Produto],MOD($J17,ROWS(tblConsorcios[Produto]))+1),"")} -> Imóvel IE480 – 240m | M17: {=IFERROR(INDEX(tblConsorcios[Valor da Carta (R$)],MOD($J17,ROWS(tblConsorcios[Produto]))+1),"")} -> 480000 | N17: {=IFERROR(INDEX(tblConsorcios[Prazo (meses)],MOD($J17,ROWS(tblConsorcios[Produto]))+1),"")} -> 240 | O17: {=IFERROR(INDEX(tblConsorcios[Parcela Mensal (R$)],MOD($J17,ROWS(tblConsorcios[Produto]))+1),"")} -> 2576 | P17: {=IFERROR(INDEX(tblClientes[Dividendo Mensal (R$)],INT($J17/ROWS(tblConsorcios[Produto]))+1),"")} -> 1500 | Q17: =IF(AND(ISNUMBER(O17),ISNUMBER(P17)),P17-O17,"") -> -1076 | R17: =IF(AND(ISNUMBER(O17),ISNUMBER(P17),O17<=P17),1,0) -> 0
A18: 10 | B18: JANDIRINHA | C18: Imóvel IE150 – 220m | D18: 150000 | E18: 220 | F18: 871.36 | G18: 4550 | H18: 3678.64 | J18: =ROW()-2 -> 16 | K18: {=IFERROR(INDEX(tblClientes[Cliente],INT($J18/ROWS(tblConsorcios[Produto]))+1),"")} -> João Silva | L18: {=IFERROR(INDEX(tblConsorcios[Produto],MOD($J18,ROWS(tblConsorcios[Produto]))+1),"")} -> Imóvel IE480 – 220m | M18: {=IFERROR(INDEX(tblConsorcios[Valor da Carta (R$)],MOD($J18,ROWS(tblConsorcios[Produto]))+1),"")} -> 480000 | N18: {=IFERROR(INDEX(tblConsorcios[Prazo (meses)],MOD($J18,ROWS(tblConsorcios[Produto]))+1),"")} -> 220 | O18: {=IFERROR(INDEX(tblConsorcios[Parcela Mensal (R$)],MOD($J18,ROWS(tblConsorcios[Produto]))+1),"")} -> 2788.36 | P18: {=IFERROR(INDEX(tblClientes[Dividendo Mensal (R$)],INT($J18/ROWS(tblConsorcios[Produto]))+1),"")} -> 1500 | Q18: =IF(AND(ISNUMBER(O18),ISNUMBER(P18)),P18-O18,"") -> -1288.36 | R18: =IF(AND(ISNUMBER(O18),ISNUMBER(P18),O18<=P18),1,0) -> 0
A19: 11 | B19: JANDIRINHA | C19: Imóvel IE140 – 200m | D19: 140000 | E19: 200 | F19: 887.6 | G19: 4550 | H19: 3662.4 | J19: =ROW()-2 -> 17 | K19: {=IFERROR(INDEX(tblClientes[Cliente],INT($J19/ROWS(tblConsorcios[Produto]))+1),"")} -> João Silva | L19: {=IFERROR(INDEX(tblConsorcios[Produto],MOD($J19,ROWS(tblConsorcios[Produto]))+1),"")} -> Imóvel IE480 – 200m | M19: {=IFERROR(INDEX(tblConsorcios[Valor da Carta (R$)],MOD($J19,ROWS(tblConsorcios[Produto]))+1),"")} -> 480000 | N19: {=IFERROR(INDEX(tblConsorcios[Prazo (meses)],MOD($J19,ROWS(tblConsorcios[Produto]))+1),"")} -> 200 | O19: {=IFERROR(INDEX(tblConsorcios[Parcela Mensal (R$)],MOD($J19,ROWS(tblConsorcios[Produto]))+1),"")} -> 3043.2 | P19: {=IFERROR(INDEX(tblClientes[Dividendo Mensal (R$)],INT($J19/ROWS(tblConsorcios[Produto]))+1),"")} -> 1500 | Q19: =IF(AND(ISNUMBER(O19),ISNUMBER(P19)),P19-O19,"") -> -1543.2 | R19: =IF(AND(ISNUMBER(O19),ISNUMBER(P19),O19<=P19),1,0) -> 0
A20: 12 | B20: JANDIRINHA | C20: Imóvel IE150 – 200m | D20: 150000 | E20: 200 | F20: 951 | G20: 4550 | H20: 3599 | J20: =ROW()-2 -> 18 | K20: {=IFERROR(INDEX(tblClientes[Cliente],INT($J20/ROWS(tblConsorcios[Produto]))+1),"")} -> João Silva | L20: {=IFERROR(INDEX(tblConsorcios[Produto],MOD($J20,ROWS(tblConsorcios[Produto]))+1),"")} -> Imóvel IE450 – 240m | M20: {=IFERROR(INDEX(tblConsorcios[Valor da Carta (R$)],MOD($J20,ROWS(tblConsorcios[Produto]))+1),"")} -> 450000 | N20: {=IFERROR(INDEX(tblConsorcios[Prazo (meses)],MOD($J20,ROWS(tblConsorcios[Produto]))+1),"")} -> 240 | O20: {=IFERROR(INDEX(tblConsorcios[Parcela Mensal (R$)],MOD($J20,ROWS(tblConsorcios[Produto]))+1),"")} -> 2415 | P20: {=IFERROR(INDEX(tblClientes[Dividendo Mensal (R$)],INT($J20/ROWS(tblConsorcios[Produto]))+1),"")} -> 1500 | Q20: =IF(AND(ISNUMBER(O20),ISNUMBER(P20)),P20-O20,"") -> -915 | R20: =IF(AND(ISNUMBER(O20),ISNUMBER(P20),O20<=P20),1,0) -> 0
A21: 13 | B21: JANDIRINHA | C21: Imóvel IE200 – 240m | D21: 200000 | E21: 240 | F21: 1073.33 | G21: 4550 | H21: 3476.67 | J21: =ROW()-2 -> 19 | K21: {=IFERROR(INDEX(tblClientes[Cliente],INT($J21/ROWS(tblConsorcios[Produto]))+1),"")} -> João Silva | L21: {=IFERROR(INDEX(tblConsorcios[Produto],MOD($J21,ROWS(tblConsorcios[Produto]))+1),"")} -> Imóvel IE450 – 220m | M21: {=IFERROR(INDEX(tblConsorcios[Valor da Carta (R$)],MOD($J21,ROWS(tblConsorcios[Produto]))+1),"")} -> 450000 | N21: {=IFERROR(INDEX(tblConsorcios[Prazo (meses)],MOD($J21,ROWS(tblConsorcios[Produto]))+1),"")} -> 220 | O21: {=IFERROR(INDEX(tblConsorcios[Parcela Mensal (R$)],MOD($J21,ROWS(tblConsorcios[Produto]))+1),"")} -> 2614.09 | P21: {=IFERROR(INDEX(tblClientes[Dividendo Mensal (R$)],INT($J21/ROWS(tblConsorcios[Produto]))+1),"")} -> 1500 | Q21: =IF(AND(ISNUMBER(O21),ISNUMBER(P21)),P21-O21,"") -> -1114.09 | R21: =IF(AND(ISNUMBER(O21),ISNUMBER(P21),O21<=P21),1,0) -> 0
... A156: 148 | B156: Maria Souza | C156: Imóvel IE550 – 220m | D156: 550000 | E156: 220 | F156: 3195 | G156: 3200 | H156: 5 | J156: =ROW()-2 -> 154 | K156: {=IFERROR(INDEX(tblClientes[Cliente],INT($J156/ROWS(tblConsorcios[Produto]))+1),"")} -> Carlos Pereira | L156: {=IFERROR(INDEX(tblConsorcios[Produto],MOD($J156,ROWS(tblConsorcios[Produto]))+1),"")} -> Imóvel IE380 – 220m | M156: {=IFERROR(INDEX(tblConsorcios[Valor da Carta (R$)],MOD($J156,ROWS(tblConsorcios[Produto]))+1),"")} -> 380000 | N156: {=IFERROR(INDEX(tblConsorcios[Prazo (meses)],MOD($J156,ROWS(tblConsorcios[Produto]))+1),"")} -> 220 | O156: {=IFERROR(INDEX(tblConsorcios[Parcela Mensal (R$)],MOD($J156,ROWS(tblConsorcios[Produto]))+1),"")} -> 2207.45 | P156: {=IFERROR(INDEX(tblClientes[Dividendo Mensal (R$)],INT($J156/ROWS(tblConsorcios[Produto]))+1),"")} -> 800 | Q156: =IF(AND(ISNUMBER(O156),ISNUMBER(P156)),P156-O156,"") -> -1407.45 | R156: =IF(AND(ISNUMBER(O156),ISNUMBER(P156),O156<=P156),1,0) -> 0
J157: =ROW()-2 -> 155 | K157: {=IFERROR(INDEX(tblClientes[Cliente],INT($J157/ROWS(tblConsorcios[Produto]))+1),"")} -> Carlos Pereira | L157: {=IFERROR(INDEX(tblConsorcios[Produto],MOD($J157,ROWS(tblConsorcios[Produto]))+1),"")} -> Imóvel IE380 – 200m | M157: {=IFERROR(INDEX(tblConsorcios[Valor da Carta (R$)],MOD($J157,ROWS(tblConsorcios[Produto]))+1),"")} -> 380000 | N157: {=IFERROR(INDEX(tblConsorcios[Prazo (meses)],MOD($J157,ROWS(tblConsorcios[Produto]))+1),"")} -> 200 | O157: {=IFERROR(INDEX(tblConsorcios[Parcela Mensal (R$)],MOD($J157,ROWS(tblConsorcios[Produto]))+1),"")} -> 2409.2 | P157: {=IFERROR(INDEX(tblClientes[Dividendo Mensal (R$)],INT($J157/ROWS(tblConsorcios[Produto]))+1),"")} -> 800 | Q157: =IF(AND(ISNUMBER(O157),ISNUMBER(P157)),P157-O157,"") -> -1609.2 | R157: =IF(AND(ISNUMBER(O157),ISNUMBER(P157),O157<=P157),1,0) -> 0
J158: =ROW()-2 -> 156 | K158: {=IFERROR(INDEX(tblClientes[Cliente],INT($J158/ROWS(tblConsorcios[Produto]))+1),"")} -> Carlos Pereira | L158: {=IFERROR(INDEX(tblConsorcios[Produto],MOD($J158,ROWS(tblConsorcios[Produto]))+1),"")} -> Imóvel IE350 – 240m | M158: {=IFERROR(INDEX(tblConsorcios[Valor da Carta (R$)],MOD($J158,ROWS(tblConsorcios[Produto]))+1),"")} -> 350000 | N158: {=IFERROR(INDEX(tblConsorcios[Prazo (meses)],MOD($J158,ROWS(tblConsorcios[Produto]))+1),"")} -> 240 | O158: {=IFERROR(INDEX(tblConsorcios[Parcela Mensal (R$)],MOD($J158,ROWS(tblConsorcios[Produto]))+1),"")} -> 1878.33 | P158: {=IFERROR(INDEX(tblClientes[Dividendo Mensal (R$)],INT($J158/ROWS(tblConsorcios[Produto]))+1),"")} -> 800 | Q158: =IF(AND(ISNUMBER(O158),ISNUMBER(P158)),P158-O158,"") -> -1078.33 | R158: =IF(AND(ISNUMBER(O158),ISNUMBER(P158),O158<=P158),1,0) -> 0
J159: =ROW()-2 -> 157 | K159: {=IFERROR(INDEX(tblClientes[Cliente],INT($J159/ROWS(tblConsorcios[Produto]))+1),"")} -> Carlos Pereira | L159: {=IFERROR(INDEX(tblConsorcios[Produto],MOD($J159,ROWS(tblConsorcios[Produto]))+1),"")} -> Imóvel IE350 – 220m | M159: {=IFERROR(INDEX(tblConsorcios[Valor da Carta (R$)],MOD($J159,ROWS(tblConsorcios[Produto]))+1),"")} -> 350000 | N159: {=IFERROR(INDEX(tblConsorcios[Prazo (meses)],MOD($J159,ROWS(tblConsorcios[Produto]))+1),"")} -> 220 | O159: {=IFERROR(INDEX(tblConsorcios[Parcela Mensal (R$)],MOD($J159,ROWS(tblConsorcios[Produto]))+1),"")} -> 2033.18 | P159: {=IFERROR(INDEX(tblClientes[Dividendo Mensal (R$)],INT($J159/ROWS(tblConsorcios[Produto]))+1),"")} -> 800 | Q159: =IF(AND(ISNUMBER(O159),ISNUMBER(P159)),P159-O159,"") -> -1233.18 | R159: =IF(AND(ISNUMBER(O159),ISNUMBER(P159),O159<=P159),1,0) -> 0
J160: =ROW()-2 -> 158 | K160: {=IFERROR(INDEX(tblClientes[Cliente],INT($J160/ROWS(tblConsorcios[Produto]))+1),"")} -> Carlos Pereira | L160: {=IFERROR(INDEX(tblConsorcios[Produto],MOD($J160,ROWS(tblConsorcios[Produto]))+1),"")} -> Imóvel IE350 – 200m | M160: {=IFERROR(INDEX(tblConsorcios[Valor da Carta (R$)],MOD($J160,ROWS(tblConsorcios[Produto]))+1),"")} -> 350000 | N160: {=IFERROR(INDEX(tblConsorcios[Prazo (meses)],MOD($J160,ROWS(tblConsorcios[Produto]))+1),"")} -> 200 | O160: {=IFERROR(INDEX(tblConsorcios[Parcela Mensal (R$)],MOD($J160,ROWS(tblConsorcios[Produto]))+1),"")} -> 2219 | P160: {=IFERROR(INDEX(tblClientes[Dividendo Mensal (R$)],INT($J160/ROWS(tblConsorcios[Produto]))+1),"")} -> 800 | Q160: =IF(AND(ISNUMBER(O160),ISNUMBER(P160)),P160-O160,"") -> -1419 | R160: =IF(AND(ISNUMBER(O160),ISNUMBER(P160),O160<=P160),1,0) -> 0
J161: =ROW()-2 -> 159 | K161: {=IFERROR(INDEX(tblClientes[Cliente],INT($J161/ROWS(tblConsorcios[Produto]))+1),"")} -> Carlos Pereira | L161: {=IFERROR(INDEX(tblConsorcios[Produto],MOD($J161,ROWS(tblConsorcios[Produto]))+1),"")} -> Imóvel IE330 – 240m | M161: {=IFERROR(INDEX(tblConsorcios[Valor da Carta (R$)],MOD($J161,ROWS(tblConsorcios[Produto]))+1),"")} -> 330000 | N161: {=IFERROR(INDEX(tblConsorcios[Prazo (meses)],MOD($J161,ROWS(tblConsorcios[Produto]))+1),"")} -> 240 | O161: {=IFERROR(INDEX(tblConsorcios[Parcela Mensal (R$)],MOD($J161,ROWS(tblConsorcios[Produto]))+1),"")} -> 1771 | P161: {=IFERROR(INDEX(tblClientes[Dividendo Mensal (R$)],INT($J161/ROWS(tblConsorcios[Produto]))+1),"")} -> 800 | Q161: =IF(AND(ISNUMBER(O161),ISNUMBER(P161)),P161-O161,"") -> -971 | R161: =IF(AND(ISNUMBER(O161),ISNUMBER(P161),O161<=P161),1,0) -> 0
J162: =ROW()-2 -> 160 | K162: {=IFERROR(INDEX(tblClientes[Cliente],INT($J162/ROWS(tblConsorcios[Produto]))+1),"")} -> Carlos Pereira | L162: {=IFERROR(INDEX(tblConsorcios[Produto],MOD($J162,ROWS(tblConsorcios[Produto]))+1),"")} -> Imóvel IE330 – 220m | M162: {=IFERROR(INDEX(tblConsorcios[Valor da Carta (R$)],MOD($J162,ROWS(tblConsorcios[Produto]))+1),"")} -> 330000 | N162: {=IFERROR(INDEX(tblConsorcios[Prazo (meses)],MOD($J162,ROWS(tblConsorcios[Produto]))+1),"")} -> 220 | O162: {=IFERROR(INDEX(tblConsorcios[Parcela Mensal (R$)],MOD($J162,ROWS(tblConsorcios[Produto]))+1),"")} -> 1917 | P162: {=IFERROR(INDEX(tblClientes[Dividendo Mensal (R$)],INT($J162/ROWS(tblConsorcios[Produto]))+1),"")} -> 800 | Q162: =IF(AND(ISNUMBER(O162),ISNUMBER(P162)),P162-O162,"") -> -1117 | R162: =IF(AND(ISNUMBER(O162),ISNUMBER(P162),O162<=P162),1,0) -> 0
J163: =ROW()-2 -> 161 | K163: {=IFERROR(INDEX(tblClientes[Cliente],INT($J163/ROWS(tblConsorcios[Produto]))+1),"")} -> Carlos Pereira | L163: {=IFERROR(INDEX(tblConsorcios[Produto],MOD($J163,ROWS(tblConsorcios[Produto]))+1),"")} -> Imóvel IE330 – 200m | M163: {=IFERROR(INDEX(tblConsorcios[Valor da Carta (R$)],MOD($J163,ROWS(tblConsorcios[Produto]))+1),"")} -> 330000 | N163: {=IFERROR(INDEX(tblConsorcios[Prazo (meses)],MOD($J163,ROWS(tblConsorcios[Produto]))+1),"")} -> 200 | O163: {=IFERROR(INDEX(tblConsorcios[Parcela Mensal (R$)],MOD($J163,ROWS(tblConsorcios[Produto]))+1),"")} -> 2092.2 | P163: {=IFERROR(INDEX(tblClientes[Dividendo Mensal (R$)],INT($J163/ROWS(tblConsorcios[Produto]))+1),"")} -> 800 | Q163: =IF(AND(ISNUMBER(O163),ISNUMBER(P163)),P163-O163,"") -> -1292.2 | R163: =IF(AND(ISNUMBER(O163),ISNUMBER(P163),O163<=P163),1,0) -> 0
J164: =ROW()-2 -> 162 | K164: {=IFERROR(INDEX(tblClientes[Cliente],INT($J164/ROWS(tblConsorcios[Produto]))+1),"")} -> Carlos Pereira | L164: {=IFERROR(INDEX(tblConsorcios[Produto],MOD($J164,ROWS(tblConsorcios[Produto]))+1),"")} -> Imóvel IE300 – 240m | M164: {=IFERROR(INDEX(tblConsorcios[Valor da Carta (R$)],MOD($J164,ROWS(tblConsorcios[Produto]))+1),"")} -> 300000 | N164: {=IFERROR(INDEX(tblConsorcios[Prazo (meses)],MOD($J164,ROWS(tblConsorcios[Produto]))+1),"")} -> 240 | O164: {=IFERROR(INDEX(tblConsorcios[Parcela Mensal (R$)],MOD($J164,ROWS(tblConsorcios[Produto]))+1),"")} -> 1610 | P164: {=IFERROR(INDEX(tblClientes[Dividendo Mensal (R$)],INT($J164/ROWS(tblConsorcios[Produto]))+1),"")} -> 800 | Q164: =IF(AND(ISNUMBER(O164),ISNUMBER(P164)),P164-O164,"") -> -810 | R164: =IF(AND(ISNUMBER(O164),ISNUMBER(P164),O164<=P164),1,0) -> 0
J165: =ROW()-2 -> 163 | K165: {=IFERROR(INDEX(tblClientes[Cliente],INT($J165/ROWS(tblConsorcios[Produto]))+1),"")} -> Carlos Pereira | L165: {=IFERROR(INDEX(tblConsorcios[Produto],MOD($J165,ROWS(tblConsorcios[Produto]))+1),"")} -> Imóvel IE300 – 220m | M165: {=IFERROR(INDEX(tblConsorcios[Valor da Carta (R$)],MOD($J165,ROWS(tblConsorcios[Produto]))+1),"")} -> 300000 | N165: {=IFERROR(INDEX(tblConsorcios[Prazo (meses)],MOD($J165,ROWS(tblConsorcios[Produto]))+1),"")} -> 220 | O165: {=IFERROR(INDEX(tblConsorcios[Parcela Mensal (R$)],MOD($J165,ROWS(tblConsorcios[Produto]))+1),"")} -> 1742.73 | P165: {=IFERROR(INDEX(tblClientes[Dividendo Mensal (R$)],INT($J165/ROWS(tblConsorcios[Produto]))+1),"")} -> 800 | Q165: =IF(AND(ISNUMBER(O165),ISNUMBER(P165)),P165-O165,"") -> -942.73 | R165: =IF(AND(ISNUMBER(O165),ISNUMBER(P165),O165<=P165),1,0) -> 0
J166: =ROW()-2 -> 164 | K166: {=IFERROR(INDEX(tblClientes[Cliente],INT($J166/ROWS(tblConsorcios[Produto]))+1),"")} -> Carlos Pereira | L166: {=IFERROR(INDEX(tblConsorcios[Produto],MOD($J166,ROWS(tblConsorcios[Produto]))+1),"")} -> Imóvel IE300 – 200m | M166: {=IFERROR(INDEX(tblConsorcios[Valor da Carta (R$)],MOD($J166,ROWS(tblConsorcios[Produto]))+1),"")} -> 300000 | N166: {=IFERROR(INDEX(tblConsorcios[Prazo (meses)],MOD($J166,ROWS(tblConsorcios[Produto]))+1),"")} -> 200 | O166: {=IFERROR(INDEX(tblConsorcios[Parcela Mensal (R$)],MOD($J166,ROWS(tblConsorcios[Produto]))+1),"")} -> 1902 | P166: {=IFERROR(INDEX(tblClientes[Dividendo Mensal (R$)],INT($J166/ROWS(tblConsorcios[Produto]))+1),"")} -> 800 | Q166: =IF(AND(ISNUMBER(O166),ISNUMBER(P166)),P166-O166,"") -> -1102 | R166: =IF(AND(ISNUMBER(O166),ISNUMBER(P166),O166<=P166),1,0) -> 0
J167: =ROW()-2 -> 165 | K167: {=IFERROR(INDEX(tblClientes[Cliente],INT($J167/ROWS(tblConsorcios[Produto]))+1),"")} -> Carlos Pereira | L167: {=IFERROR(INDEX(tblConsorcios[Produto],MOD($J167,ROWS(tblConsorcios[Produto]))+1),"")} -> Imóvel IE240 – 240m | M167: {=IFERROR(INDEX(tblConsorcios[Valor da Carta (R$)],MOD($J167,ROWS(tblConsorcios[Produto]))+1),"")} -> 240000 | N167: {=IFERROR(INDEX(tblConsorcios[Prazo (meses)],MOD($J167,ROWS(tblConsorcios[Produto]))+1),"")} -> 240 | O167: {=IFERROR(INDEX(tblConsorcios[Parcela Mensal (R$)],MOD($J167,ROWS(tblConsorcios[Produto]))+1),"")} -> 1288 | P167: {=IFERROR(INDEX(tblClientes[Dividendo Mensal (R$)],INT($J167/ROWS(tblConsorcios[Produto]))+1),"")} -> 800 | Q167: =IF(AND(ISNUMBER(O167),ISNUMBER(P167)),P167-O167,"") -> -488 | R167: =IF(AND(ISNUMBER(O167),ISNUMBER(P167),O167<=P167),1,0) -> 0
J168: =ROW()-2 -> 166 | K168: {=IFERROR(INDEX(tblClientes[Cliente],INT($J168/ROWS(tblConsorcios[Produto]))+1),"")} -> Carlos Pereira | L168: {=IFERROR(INDEX(tblConsorcios[Produto],MOD($J168,ROWS(tblConsorcios[Produto]))+1),"")} -> Imóvel IE240 – 220m | M168: {=IFERROR(INDEX(tblConsorcios[Valor da Carta (R$)],MOD($J168,ROWS(tblConsorcios[Produto]))+1),"")} -> 240000 | N168: {=IFERROR(INDEX(tblConsorcios[Prazo (meses)],MOD($J168,ROWS(tblConsorcios[Produto]))+1),"")} -> 220 | O168: {=IFERROR(INDEX(tblConsorcios[Parcela Mensal (R$)],MOD($J168,ROWS(tblConsorcios[Produto]))+1),"")} -> 1394.18 | P168: {=IFERROR(INDEX(tblClientes[Dividendo Mensal (R$)],INT($J168/ROWS(tblConsorcios[Produto]))+1),"")} -> 800 | Q168: =IF(AND(ISNUMBER(O168),ISNUMBER(P168)),P168-O168,"") -> -594.18 | R168: =IF(AND(ISNUMBER(O168),ISNUMBER(P168),O168<=P168),1,0) -> 0
... J9451: =ROW()-2 -> 9449 | K9451: {=IFERROR(INDEX(tblClientes[Cliente],INT($J9451/ROWS(tblConsorcios[Produto]))+1),"")} | L9451: {=IFERROR(INDEX(tblConsorcios[Produto],MOD($J9451,ROWS(tblConsorcios[Produto]))+1),"")} -> Imóvel IE120 – 200m | M9451: {=IFERROR(INDEX(tblConsorcios[Valor da Carta (R$)],MOD($J9451,ROWS(tblConsorcios[Produto]))+1),"")} -> 120000 | N9451: {=IFERROR(INDEX(tblConsorcios[Prazo (meses)],MOD($J9451,ROWS(tblConsorcios[Produto]))+1),"")} -> 200 | O9451: {=IFERROR(INDEX(tblConsorcios[Parcela Mensal (R$)],MOD($J9451,ROWS(tblConsorcios[Produto]))+1),"")} -> 760.8 | P9451: {=IFERROR(INDEX(tblClientes[Dividendo Mensal (R$)],INT($J9451/ROWS(tblConsorcios[Produto]))+1),"")} | Q9451: =IF(AND(ISNUMBER(O9451),ISNUMBER(P9451)),P9451-O9451,"") | R9451: =IF(AND(ISNUMBER(O9451),ISNUMBER(P9451),O9451<=P9451),1,0) -> 0
